<?xml version="1.0"?>
<robot name="my tilting robot">
<link name="base_link">  <!--first link-->
 <visual>
    
    <geometry>
     <cylinder radius="0.2" length="0.01"/>
    </geometry>
    <origin rpy="0.0 0.0 0.0" xyz="0.0 0.0 0.0"/>
    <material name="black"><!--yellow tha before :)-->
     <color rgba="1 1 0 1"/>   
    </material>
 </visual>
</link>

<joint name="pan_joint" type="revolute"> <!--1st joint-->
    <parent link="base_link"/>
    <child link="pan_link"/>
    <origin xyz="0 0 0.1"/>
    <axis xyz="0.0 0.0 1"/>
</joint>

<link name="pan_link"> <!-- 2nd link-->
 <visual>
  <geometry>
      <cylinder radius="0.04" length="0.4"/>
  </geometry>
  <origin rpy="0.0 0.0 0.0" xyz="0.0 0.0 0.09"/>
  <material name="blue">
   <color rgba="0.0 0.0 1.0 0.0"/> <!--0 0 1 1 for red-->
   
  </material>
     
 </visual>
    
</link>

<joint name="tilt_joint" type="revolute"> <!--2nd Joint-->
    <parent link="pan_link"/>
    <child link="tilt_link"/>
    <origin xyz="0.0 0.0 0.2"/>
    <axis xyz="0.0 1.0 0.0"/>
</joint>

<link name="tit_link">
 <visual>
     <geometry>
         <cylinder radius="0.04" length="0.4"/>
     </geometry>
     <origin rpy="0.0 1.5 0.0"/ xyz="0.0 0.0 0.0">
     <material name="green">
     <color rgba="1 0.0 0.0 1"/>
         
     </material>
 </visual>
</link>
</robot>